scripts/test_case5.txt
40
0 o
1 o
2 o
3 o
4 o
5 o
6 o
7 o
8 o
9 o
10 o
11 o
12 o
13 o
14 o
15 o
16 o
17 o
18 o
19 o
20 o
21 o
22 o
23 o
24 o
25 o
26 o
27 o
28 o
29 o
30 o
31 o
32 o
33 o
34 o
35 o
36 o
37 o
38 o
39 o
.
37 S 13790428 AMZN 77640 3642
39 B 9285028 AAPL 73804 4932
38 S 72143833 MSFT 57874 4676
39 B 75407887 MSFT 46114 6801
37 C 13790428
38 C 72143833
39 S 4284934 AAPL 97720 4687
38 S 33984358 GOOG 79986 1533
33 S 57781195 MSFT 63063 8681
39 C 75407887
39 B 20069666 MSFT 91173 3428
37 B 22791437 AMZN 55078 1168
38 B 26773838 AAPL 90900 6575
38 B 78393467 AMZN 33565 2489
37 B 76385533 MSFT 53180 3412
39 S 52726473 AMZN 82820 8348
39 S 3158082 GOOG 67973 7217
36 S 1372557 GOOG 2087 6171
39 B 94980927 AMZN 58583 3381
38 C 78393467
38 S 16694372 MSFT 51199 7787
37 C 76385533
39 S 15135238 AAPL 41778 5910
39 C 9285028
39 C 9285028
37 S 93190372 MSFT 16809 9394
39 B 57192997 AAPL 59364 8525
37 S 68902253 AMZN 85933 2038
39 B 655830 GOOG 25222 4441
39 S 59398654 AAPL 11031 3195
39 C 20069666
39 B 52532728 AAPL 2968 273
37 C 68902253
39 B 31777384 AMZN 9081 1974
37 C 68902253
37 B 6934523 AAPL 20151 9944
38 B 11044168 AAPL 33538 5630
39 C 57192997
35 B 67125489 MSFT 83083 199
39 B 90874065 GOOG 49525 7081
39 C 15135238
39 C 94980927
37 B 16578935 AMZN 93352 7399
37 C 93190372
33 S 59131821 AMZN 38198 3594
39 S 96502367 GOOG 39240 2914
39 B 9354360 AMZN 46301 2586
34 B 70806396 AAPL 42046 5034
38 B 94552466 GOOG 4051 5705
36 B 5447875 AMZN 58143 4240
39 B 17511426 GOOG 51647 8950
36 C 1372557
39 S 31410369 GOOG 76975 2423
39 S 71504084 AAPL 27693 1296
38 C 78393467
39 C 15135238
39 C 9285028
39 C 9285028
39 B 59984268 GOOG 26319 5323
39 B 73359426 AMZN 29143 9669
37 C 68902253
37 C 76385533
38 C 94552466
39 C 31410369
38 C 72143833
38 C 26773838
39 S 37599331 GOOG 31482 6812
39 S 88346859 MSFT 21044 6135
39 S 35261245 AMZN 25703 9065
39 C 57192997
36 S 98529256 GOOG 7985 9268
39 C 59398654
39 B 41533168 AMZN 54162 5413
38 B 93848507 MSFT 66501 5764
39 S 82188856 MSFT 99905 3833
39 B 99769218 AMZN 30518 3302
36 C 98529256
39 B 87275820 AMZN 53079 1115
37 C 22791437
39 C 17511426
39 B 22447486 AAPL 24259 3351
36 C 98529256
36 C 98529256
39 B 13789678 GOOG 56964 7080
39 C 17511426
39 S 55716974 AAPL 60095 3775
38 C 16694372
39 S 97290644 AMZN 99741 3717
38 C 72143833
36 C 5447875
39 C 59984268
35 S 95488806 MSFT 61954 9231
39 B 64074202 GOOG 6853 4793
39 C 13789678
38 C 33984358
38 S 90546584 AAPL 74665 3172
38 S 2055482 AAPL 15990 3390
36 S 89502174 AMZN 58681 3692
37 B 50211786 AAPL 76462 7371
38 S 33573940 AAPL 7597 5942
39 S 69315943 AAPL 84963 9631
39 S 78291425 MSFT 2811 2726
38 C 94552466
38 B 99349762 AMZN 15181 8245
39 C 41533168
39 S 10963945 AMZN 45875 5451
38 B 37229251 GOOG 28693 859
38 B 83566617 AAPL 25600 4188
38 S 78411583 GOOG 5040 4933
39 S 5738564 GOOG 69509 146
39 B 41860432 MSFT 38727 4417
39 B 86043142 AMZN 45490 9217
38 B 54305850 AMZN 94599 6634
39 S 49065642 GOOG 22215 1839
38 C 90546584
39 C 69315943
39 B 17436111 GOOG 84086 4623
38 S 22814206 MSFT 86894 7613
38 S 78416003 GOOG 44435 6177
38 B 64559075 GOOG 40599 5850
39 S 18347980 MSFT 58244 9486
39 B 87376958 AMZN 32672 6271
37 B 39462673 AMZN 70594 546
37 B 53620071 GOOG 19247 3170
38 C 26773838
38 B 9023106 GOOG 39298 65
39 S 94063142 AMZN 69813 4580
38 S 45776914 GOOG 43212 6081
39 S 26961597 MSFT 35691 9111
39 S 80342568 AMZN 37970 225
38 S 39503869 AAPL 67336 8933
39 S 1715613 AAPL 62573 7784
34 C 70806396
39 C 80342568
39 C 80342568
38 C 22814206
39 S 444527 GOOG 30273 6924
39 C 86043142
39 C 87376958
36 C 98529256
39 B 3161917 AMZN 86340 5333
37 S 90812074 MSFT 43574 9379
39 C 94980927
38 C 78411583
37 B 7678630 GOOG 9784 4108
37 B 41617653 MSFT 61718 6083
39 B 9929347 AAPL 80726 3420
39 S 29010274 GOOG 62575 4239
38 B 26768801 AMZN 13717 3626
39 S 42880114 MSFT 11788 8770
39 C 55716974
39 S 68535082 AAPL 82966 2723
38 C 78411583
39 S 42012936 AMZN 95372 797
39 C 444527
39 C 31777384
39 S 71683630 AAPL 10080 3604
38 S 29972367 GOOG 46634 6465
39 S 56764395 GOOG 66155 4533
39 C 78291425
39 C 82188856
39 S 43690917 AMZN 75233 1669
37 C 16578935
39 B 6095631 AMZN 87729 7808
39 B 29126078 AMZN 72305 7690
39 C 57192997
39 S 94938676 MSFT 12390 696
37 B 18462033 GOOG 42184 6963
38 C 26768801
39 B 26509306 AMZN 13200 8416
39 S 58084312 AAPL 24502 4084
36 C 89502174
37 B 73954998 MSFT 37384 7258
38 B 37110070 AMZN 60731 1357
38 B 39090292 MSFT 62786 9406
39 B 6159852 AMZN 28806 1395
39 B 95204068 AAPL 62288 6062
39 S 17046947 AMZN 40497 7548
34 S 23237915 GOOG 55978 4143
38 C 37229251
39 B 94822575 GOOG 29730 43
39 S 54231543 GOOG 42009 2532
39 B 48422196 AAPL 94046 1602
37 B 82166363 AAPL 18603 656
39 B 1867398 AAPL 61438 5380
37 S 94551946 AMZN 71031 3371
39 S 64695412 AMZN 82120 2082
36 C 5447875
37 S 17129059 GOOG 43936 4759
38 S 58923111 AMZN 55887 5170
35 S 82433604 MSFT 62914 7778
37 S 3688732 GOOG 55197 6778
36 B 26958701 GOOG 92402 8197
38 B 2881550 GOOG 7842 9716
38 C 33984358
38 B 72579094 GOOG 67314 9266
38 S 18808384 AMZN 91335 2267
37 B 15106868 AMZN 64369 1779
38 B 87395849 GOOG 85728 2404
38 S 22818768 AAPL 30058 1825
36 S 31946291 AMZN 2015 1659
38 C 72143833
37 B 35718831 GOOG 5748 8613
38 S 88052990 AMZN 90622 5176
38 C 72579094
38 S 59874488 GOOG 60686 9704
38 B 94058472 MSFT 6746 8334
38 B 25813987 AMZN 93837 4505
35 S 35169975 AAPL 14577 9449
36 C 5447875
37 C 18462033
27 B 91300446 MSFT 26958 962
35 C 35169975
36 B 65150417 GOOG 77420 4073
38 C 26768801
38 B 73937419 AAPL 61173 9165
38 S 75351913 GOOG 79827 5810
37 S 1058423 GOOG 12042 2648
37 C 41617653
38 B 79760360 MSFT 51784 7547
38 C 54305850
36 S 75098751 AAPL 68476 8227
38 S 97683747 MSFT 23366 3940
37 S 72700961 GOOG 6843 5684
31 B 1103648 GOOG 8794 5071
34 B 14561695 GOOG 58355 401
38 S 65649342 GOOG 62181 3004
36 C 98529256
37 B 44783425 AAPL 74551 6043
38 S 46061536 MSFT 30595 3145
38 B 68842431 AMZN 36454 6970
37 C 53620071
38 C 59874488
34 S 96977285 GOOG 56347 1152
38 C 97683747
38 C 75351913
38 C 97683747
38 S 829224 MSFT 44447 9937
36 C 1372557
35 C 95488806
38 B 33762367 MSFT 14912 2371
38 C 90546584
36 C 98529256
38 C 39503869
36 B 698748 AAPL 20349 2565
37 C 53620071
38 B 13156222 AAPL 10401 3008
37 S 65201565 MSFT 28943 7056
36 C 98529256
36 S 70333195 GOOG 44520 3487
37 S 67039143 MSFT 38537 6670
38 S 65173246 GOOG 98930 286
34 B 69993146 GOOG 77446 6000
37 B 67138908 GOOG 41863 1808
34 B 96989463 AAPL 82217 1027
37 B 61034771 AMZN 85007 2377
32 S 6668685 AMZN 75795 739
38 B 43363779 GOOG 67250 2596
38 S 46272115 GOOG 99033 9081
36 S 53810409 GOOG 71317 7981
38 S 40865005 MSFT 2321 1493
37 S 65872455 AMZN 65303 7124
35 S 67193468 GOOG 33416 9721
38 C 40865005
38 S 75824049 AAPL 41991 2994
38 C 22818768
32 S 73097077 MSFT 40796 4228
38 S 86935795 AAPL 37716 8731
38 S 56526887 GOOG 61999 3920
38 S 95613056 AMZN 2473 9454
35 C 67193468
37 C 35718831
38 B 67432605 GOOG 2586 5063
38 B 77772477 AAPL 73919 2039
37 C 67138908
38 S 34887155 AMZN 84319 8782
37 C 82166363
38 S 38589561 MSFT 81753 6735
37 C 94551946
38 C 78411583
38 B 41453690 MSFT 91856 2635
38 S 74807446 MSFT 45198 5164
37 C 82166363
38 B 27514059 AAPL 81584 1939
38 C 25813987
35 S 63989650 AAPL 51333 8250
38 C 77772477
38 S 44398210 AAPL 80684 7818
35 S 6683939 AMZN 45996 4159
38 S 10812853 MSFT 73671 1322
37 S 21371398 AMZN 56449 4033
35 C 35169975
38 C 65173246
38 B 15190279 AAPL 32302 5363
34 C 14561695
38 S 17635079 MSFT 36072 1679
33 C 57781195
33 S 17682996 AMZN 17698 7098
36 S 92351679 AAPL 90645 5410
34 S 38205643 GOOG 35896 3170
36 S 5439201 AAPL 75424 2091
33 B 71457850 MSFT 62157 4751
37 S 54005770 MSFT 44346 8746
36 C 26958701
37 C 94551946
36 C 5439201
37 B 61215063 AMZN 28872 7986
37 B 97744427 AAPL 89143 7924
34 C 70806396
34 S 75641879 GOOG 39001 7683
34 S 9688005 AAPL 35087 1924
37 C 6934523
37 C 6934523
34 C 23237915
37 B 14197537 AAPL 57216 4419
37 S 33124402 AMZN 51046 9280
35 C 63989650
36 S 31423127 GOOG 90196 8601
36 S 31556657 GOOG 20756 1145
37 C 14197537
37 S 39631971 AAPL 55492 1796
37 B 84451158 GOOG 84422 8259
36 C 92351679
