scripts/test_case6.txt
40
0 o
1 o
2 o
3 o
4 o
5 o
6 o
7 o
8 o
9 o
10 o
11 o
12 o
13 o
14 o
15 o
16 o
17 o
18 o
19 o
20 o
21 o
22 o
23 o
24 o
25 o
26 o
27 o
28 o
29 o
30 o
31 o
32 o
33 o
34 o
35 o
36 o
37 o
38 o
39 o
.
38 S 36291922 GOOG 18437 9836
37 B 97883440 AAPL 39079 6868
38 C 36291922
38 B 66547252 AAPL 94057 7927
38 S 10652767 AMZN 45331 2663
39 S 22473645 AAPL 28309 3178
39 C 22473645
39 B 32142127 GOOG 41762 5219
37 S 87107397 AMZN 33336 2984
36 B 89986036 MSFT 55279 3633
38 B 11891006 AMZN 90010 3148
34 S 5660003 GOOG 51094 3966
39 B 34493394 GOOG 83524 8406
37 S 21310879 AAPL 56238 388
37 S 16298627 AMZN 52419 1911
39 C 34493394
39 C 22473645
27 S 68745665 MSFT 43488 9590
39 S 34251969 GOOG 43404 4759
39 S 85059531 AAPL 7463 4815
38 C 11891006
36 B 88962681 AMZN 64963 6091
39 C 34251969
38 S 75898132 AAPL 12253 5292
38 B 53009334 MSFT 17936 2229
39 B 86782574 MSFT 76476 6091
39 S 48290496 MSFT 87141 7818
39 C 48290496
39 C 86782574
38 C 75898132
35 B 77676926 AMZN 29003 1350
39 S 68620372 MSFT 78740 9860
37 B 15255589 GOOG 7601 6385
39 S 5488982 MSFT 95026 337
34 B 11655595 AMZN 46102 8004
38 S 79583544 AMZN 22700 1827
39 C 48290496
38 S 19019244 AMZN 67026 7594
39 B 66820300 AMZN 37607 1382
39 B 47752819 GOOG 55122 3265
39 S 67759589 GOOG 37329 7903
38 B 35296895 AMZN 22607 7855
39 B 26532832 GOOG 62910 5465
39 B 17979171 MSFT 99221 5042
39 B 14811802 AMZN 33892 419
39 S 33982084 AMZN 84188 6761
39 C 47752819
39 S 503327 AAPL 28725 2773
39 S 76585066 AMZN 83798 7299
38 S 2863569 AMZN 91038 9736
39 C 5488982
39 S 28618384 GOOG 29332 1972
38 B 69427818 AAPL 49642 7476
39 B 92170016 GOOG 52780 9957
37 S 95019941 AMZN 38781 7478
39 S 49851202 AMZN 61630 338
37 S 88737868 AAPL 29381 1670
39 B 39045911 AMZN 1146 4607
37 B 49747073 MSFT 62450 4967
39 B 9224667 GOOG 31561 9769
39 C 67759589
39 C 14811802
39 C 68620372
37 C 15255589
39 S 19326041 AMZN 5687 170
39 B 56484132 GOOG 77616 6890
37 B 27797077 MSFT 68848 2881
36 C 89986036
38 C 10652767
39 B 50425866 AMZN 14193 5025
39 B 21979489 MSFT 64328 8294
38 C 35296895
39 B 57081207 GOOG 33637 1743
39 B 21032926 AMZN 84215 2104
39 S 22184497 GOOG 55370 1431
37 B 91186840 AMZN 41964 1824
39 C 48290496
39 C 21032926
36 C 89986036
39 C 56484132
38 B 14801190 AAPL 76940 4886
36 B 12520612 AAPL 4278 1095
36 B 77583129 AAPL 53053 5967
39 B 85461381 AAPL 59109 7703
36 S 99135972 AAPL 79125 7157
38 S 5778908 MSFT 63355 6879
36 S 93184893 AMZN 8870 421
38 B 91499024 AAPL 79356 4517
38 C 10652767
39 C 92170016
34 B 85700275 AAPL 11776 3473
39 S 55322561 AMZN 86816 7581
39 C 39045911
37 S 12913932 GOOG 98838 8676
38 B 88246148 AMZN 10237 3466
39 C 19326041
39 S 35092987 MSFT 41743 4516
34 C 85700275
36 B 61395002 MSFT 51689 4583
37 C 15255589
34 B 40894731 AMZN 21611 7857
39 S 29966094 GOOG 37833 9481
39 S 92430728 GOOG 56405 7757
39 B 24229011 MSFT 65892 9314
38 C 11891006
39 S 34385018 AMZN 33369 9792
36 C 61395002
39 B 30036052 AAPL 33209 474
39 B 41858976 GOOG 96747 6190
39 S 24309343 AMZN 61162 6815
36 S 5588053 MSFT 45994 9062
38 S 87603880 MSFT 55412 7521
37 B 95981023 MSFT 61251 3015
37 C 95019941
39 S 40510225 AAPL 25042 8638
39 C 56484132
39 C 21979489
39 C 22473645
37 S 20716624 AMZN 77241 8594
39 S 19740143 GOOG 32271 4986
39 C 33982084
39 B 65113677 MSFT 69884 6861
39 C 40510225
39 S 62300208 AMZN 51249 3404
38 S 13913058 AAPL 68096 2589
39 C 19740143
39 C 21032926
37 B 77954115 MSFT 24163 6904
39 C 30036052
36 B 82853038 GOOG 29900 4942
39 B 72941797 MSFT 10670 1390
39 C 92170016
39 C 21032926
39 S 84586517 MSFT 44932 4400
39 C 26532832
39 B 62995963 GOOG 3672 6751
38 C 14801190
38 B 97268318 GOOG 41651 6165
39 C 62300208
39 B 90506500 MSFT 13144 8198
39 B 61184389 AAPL 38854 7396
38 C 91499024
37 C 49747073
37 C 97883440
38 B 62337427 AAPL 80045 3678
39 S 55356024 GOOG 9968 1918
39 S 32221048 AMZN 77435 8685
39 S 16962582 GOOG 34908 215
38 B 56728275 AMZN 60021 4207
39 S 31644861 MSFT 92371 4581
38 C 53009334
38 C 79583544
39 S 66479836 AAPL 74056 8470
39 B 2892462 AAPL 41846 2760
39 B 67300494 AMZN 66943 1237
32 S 6359950 MSFT 59325 5385
35 C 77676926
39 B 40083014 MSFT 96511 8730
39 C 55322561
39 C 47752819
39 B 79757909 AAPL 70790 4141
37 C 95019941
39 C 34385018
35 B 86166632 AMZN 66246 9759
39 C 47752819
39 B 33609185 GOOG 2342 4610
39 C 22184497
39 B 19824729 AMZN 76527 8537
39 C 24309343
39 C 9224667
38 C 10652767
39 B 29947039 GOOG 42506 4624
39 C 84586517
38 B 43625038 GOOG 8936 7769
37 B 52677842 GOOG 45382 6545
36 S 57283549 AMZN 77542 664
37 B 65827464 GOOG 64991 2435
38 C 62337427
31 S 47477539 AAPL 6750 2102
38 S 3838741 MSFT 36439 3828
38 C 36291922
38 S 97031026 AMZN 27590 9746
37 B 73196617 AAPL 98987 2417
38 B 79070154 MSFT 53173 2897
36 B 86190201 AAPL 4994 4445
37 B 48915497 AAPL 35081 6862
38 C 79070154
36 S 73488013 MSFT 56257 7100
38 C 62337427
37 B 23119138 AAPL 18701 1459
38 B 13445738 AMZN 73256 2755
36 B 16195607 AAPL 86933 3257
36 B 89788509 AAPL 17030 2732
37 C 95981023
37 C 88737868
38 S 73943366 AAPL 59547 8281
38 B 99968605 AAPL 64119 9654
38 C 13913058
37 C 52677842
38 C 99968605
38 S 53703652 MSFT 52435 2408
33 B 97312430 MSFT 75594 9166
36 S 94843104 MSFT 99723 7460
38 B 17668773 AAPL 37906 4577
38 C 2863569
36 C 86190201
38 C 79583544
36 B 4223336 AMZN 85635 238
37 B 26395018 AAPL 47168 5748
38 B 11395455 AAPL 50047 5812
38 S 84561265 GOOG 56031 5918
37 S 9117267 AAPL 22305 5407
37 C 26395018
38 C 97268318
37 B 40196259 AAPL 5983 9713
38 B 36413716 MSFT 20871 4979
38 S 45089594 AMZN 41930 9329
38 S 73980384 AMZN 50930 6194
38 B 50632801 MSFT 43387 9499
38 C 2863569
38 B 63478779 GOOG 24916 4516
38 S 67411649 AAPL 51876 8547
36 C 61395002
38 B 4432380 AAPL 23943 2520
37 S 66188517 AMZN 67176 9347
36 B 22869 AMZN 63413 4841
38 S 60498052 AAPL 75022 2220
38 B 81061023 GOOG 16272 24
35 B 18800571 MSFT 11550 8153
38 C 2863569
37 C 91186840
36 C 61395002
37 S 91109852 AAPL 87185 8221
34 C 5660003
38 B 56786711 AMZN 10555 3157
37 C 87107397
38 C 17668773
37 C 91109852
37 C 65827464
38 C 2863569
36 C 22869
38 S 48469215 GOOG 4607 1787
33 S 8806892 AAPL 15449 2543
37 S 38027914 GOOG 56338 4467
36 B 42808877 MSFT 52319 2302
38 S 62714102 MSFT 99332 3587
38 C 87603880
38 S 63015041 MSFT 82376 4669
37 C 48915497
36 B 45524846 GOOG 68681 8114
36 B 35625077 MSFT 97586 5078
38 S 73112853 GOOG 82256 5462
38 B 81307212 AAPL 45611 3865
35 B 28548580 GOOG 62790 3879
37 B 79450515 AAPL 31261 5718
38 B 23481395 GOOG 57021 1161
37 S 59009395 GOOG 35494 1255
36 C 35625077
37 B 68778187 MSFT 71053 1402
38 S 9007603 AMZN 36365 2437
38 B 53348089 MSFT 13087 5427
36 B 13277819 MSFT 71007 2376
38 S 26809679 AMZN 73721 8924
38 B 36292880 GOOG 47849 3979
36 B 47941469 MSFT 85588 8282
38 C 63015041
37 S 22739325 AAPL 81715 323
35 B 97959785 AMZN 65285 1693
33 B 2648173 AMZN 8085 6683
36 C 4223336
29 S 67307367 GOOG 50245 7328
37 C 38027914
38 S 21534867 AAPL 83832 2111
38 C 63478779
36 S 23973726 MSFT 39771 8140
38 B 61453629 GOOG 37669 2173
38 C 50632801
38 S 36556138 GOOG 30204 8838
37 B 92220780 AMZN 55789 7195
38 C 81061023
31 B 49202820 AMZN 56595 6309
35 S 3468607 AMZN 59212 8813
38 C 3838741
38 C 53348089
36 C 94843104
38 S 55057557 GOOG 99726 7216
37 C 15255589
38 B 55536046 AAPL 53375 5405
37 S 50566145 MSFT 6184 3945
38 C 63478779
38 C 63015041
38 S 49415664 AMZN 57311 9683
38 S 39515829 MSFT 99054 1732
37 B 13456516 MSFT 22986 6404
31 C 49202820
38 B 13402145 MSFT 99165 3666
38 C 14801190
38 B 20747090 AMZN 39792 643
37 S 5500752 AMZN 32838 665
34 S 87770576 MSFT 23033 6825
38 B 42206126 AAPL 44000 2285
37 S 51821071 AMZN 19507 3844
32 B 48462812 AAPL 58574 5247
38 C 62337427
38 B 31568789 MSFT 40017 9836
36 B 77983216 GOOG 57811 5378
38 S 68655102 GOOG 49898 8267
38 S 60208592 AAPL 83702 4832
37 S 78078497 AAPL 34527 9900
33 S 68991982 AAPL 70665 3967
35 B 55533665 GOOG 66611 7603
37 B 32363951 GOOG 97442 2574
35 B 35484710 AAPL 96549 3311
35 B 71634217 AAPL 59767 1788
36 C 16195607
37 B 51846280 GOOG 94155 3481
37 C 5500752
37 B 61190506 AAPL 71791 8577
37 C 68778187
36 B 23010860 AMZN 94219 210
34 B 75191749 AAPL 80773 5737
